<sdf version='1.5'>
  <world name='default'>
    <light name='sun' type='directional'>
      <cast_shadows>1</cast_shadows>
      <pose>0 0 10 0 -0 0</pose>
      <diffuse>0.8 0.8 0.8 1</diffuse>
      <specular>0.2 0.2 0.2 1</specular>
      <attenuation>
        <range>1000</range>
        <constant>0.9</constant>
        <linear>0.01</linear>
        <quadratic>0.001</quadratic>
      </attenuation>
      <direction>-0.5 0.1 -0.9</direction>
    </light>
    <physics name='default_physics' default='0' type='ode'>
      <max_step_size>0.001</max_step_size>
      <real_time_factor>1</real_time_factor>
      <real_time_update_rate>1000</real_time_update_rate>
      <gravity>0 0 -9.8</gravity>
      <magnetic_field>6e-06 2.3e-05 -4.2e-05</magnetic_field>
    </physics>
    <scene>
      <sky>
        <clouds>
          <speed>12</speed>
        </clouds>
      </sky>
      <ambient>0.4 0.4 0.4 1</ambient>
      <background>0.7 0.7 0.7 1</background>
      <shadows>1</shadows>
    </scene>
    <audio>
      <device>default</device>
    </audio>
    <spherical_coordinates>
      <surface_model>EARTH_WGS84</surface_model>
      <latitude_deg>0</latitude_deg>
      <longitude_deg>0</longitude_deg>
      <elevation>0</elevation>
      <heading_deg>0</heading_deg>
    </spherical_coordinates>
    <model name='Paris_segment'>
      <link name='link_0'>
        <pose>3e-06 3e-06 1e-06 0 -0 0</pose>
        <self_collide>0</self_collide>
        <kinematic>0</kinematic>
        <gravity>1</gravity>
        <inertial>
          <mass>1</mass>
          <pose>0 0 0 0 -0 0</pose>
          <inertia>
            <ixx>1</ixx>
            <ixy>0</ixy>
            <ixz>0</ixz>
            <iyy>1</iyy>
            <iyz>0</iyz>
            <izz>1</izz>
          </inertia>
        </inertial>
        <visual name='visual'>
          <pose>0 0 0 0 -0 0</pose>
          <geometry>
            <mesh>
              <uri>model://Paris_segment/shadeless_paris_segment2.dae</uri>
              <scale>0.5 0.5 0.5</scale>
            </mesh>
          </geometry>
          <cast_shadows>0</cast_shadows>
          <transparency>0</transparency>
          <material>
            <shader type='pixel'>
              <normal_map>__default__</normal_map>
            </shader>
            <lighting>0</lighting>
          </material>
        </visual>
        <collision name='collision'>
          <laser_retro>0</laser_retro>
          <max_contacts>10</max_contacts>
          <pose>0 0 0 0 -0 0</pose>
          <geometry>
            <mesh>
              <uri>/Users/selfcar/.gazebo/models/Paris_segment/shadeless_paris_segment2.dae</uri>
              <scale>0.5 0.5 0.5</scale>
            </mesh>
          </geometry>
          <surface>
            <friction>
              <ode>
                <mu>1</mu>
                <mu2>1</mu2>
                <fdir1>0 0 0</fdir1>
                <slip1>0</slip1>
                <slip2>0</slip2>
              </ode>
            </friction>
            <bounce>
              <restitution_coefficient>0</restitution_coefficient>
              <threshold>1e+06</threshold>
            </bounce>
            <contact>
              <collide_without_contact>0</collide_without_contact>
              <collide_without_contact_bitmask>1</collide_without_contact_bitmask>
              <collide_bitmask>1</collide_bitmask>
              <ode>
                <soft_cfm>0</soft_cfm>
                <soft_erp>0.2</soft_erp>
                <kp>1e+13</kp>
                <kd>1</kd>
                <max_vel>0.01</max_vel>
                <min_depth>0</min_depth>
              </ode>
              <bullet>
                <split_impulse>1</split_impulse>
                <split_impulse_penetration_threshold>-0.01</split_impulse_penetration_threshold>
                <soft_cfm>0</soft_cfm>
                <soft_erp>0.2</soft_erp>
                <kp>1e+13</kp>
                <kd>1</kd>
              </bullet>
            </contact>
          </surface>
        </collision>
      </link>
      <static>1</static>
      <allow_auto_disable>1</allow_auto_disable>
      <pose>0 0 0 0 -0 0</pose>
    </model>
    <model name='car'>
      <link name='chassis'>
        <pose>0 0 0.35 0 -0 0</pose>
        <inertial>
          <mass>100</mass>
          <inertia>
            <ixx>1</ixx>
            <ixy>0</ixy>
            <ixz>0</ixz>
            <iyy>1</iyy>
            <iyz>0</iyz>
            <izz>1</izz>
          </inertia>
        </inertial>
        <collision name='chassis_collision'>
          <geometry>
            <box>
              <size>2 0.8 0.2</size>
            </box>
          </geometry>
          <max_contacts>10</max_contacts>
          <surface>
            <contact>
              <ode/>
            </contact>
            <bounce/>
            <friction>
              <ode/>
            </friction>
          </surface>
        </collision>
        <visual name='chassis_visual'>
          <pose>0.1 0 -0.2 0 -0 1.57079</pose>
          <geometry>
            <mesh>
              <uri>/Users/selfcar/Desktop/Self-Driving-Comps/models/sdcCar/cooper-test.dae</uri>
            </mesh>
          </geometry>
        </visual>
        <self_collide>0</self_collide>
        <kinematic>0</kinematic>
        <gravity>1</gravity>
      </link>
      <link name='front_left_wheel'>
        <inertial>
          <mass>10</mass>
          <inertia>
            <ixx>1</ixx>
            <ixy>0</ixy>
            <ixz>0</ixz>
            <iyy>1</iyy>
            <iyz>0</iyz>
            <izz>1</izz>
          </inertia>
        </inertial>
        <pose>0.8 0.5 0.3 0 1.57079 1.57079</pose>
        <collision name='front_left_wheel_collision'>
          <geometry>
            <cylinder>
              <radius>0.21</radius>
              <length>0.1</length>
            </cylinder>
          </geometry>
          <max_contacts>10</max_contacts>
          <surface>
            <contact>
              <ode/>
            </contact>
            <bounce/>
            <friction>
              <ode/>
            </friction>
          </surface>
        </collision>
        <visual name='front_left_wheel_visual'>
          <geometry>
            <mesh>
              <uri>/Users/selfcar/Desktop/Self-Driving-Comps/models/sdcCar/wheel.stl</uri>
            </mesh>
          </geometry>
          <material>
            <script>
              <uri>file://media/materials/scripts/gazebo.material</uri>
              <name>Gazebo/Black</name>
            </script>
          </material>
        </visual>
        <self_collide>0</self_collide>
        <kinematic>0</kinematic>
        <gravity>1</gravity>
      </link>
      <link name='front_right_wheel'>
        <pose>0.8 -0.5 0.3 0 1.57079 -1.57079</pose>
        <inertial>
          <mass>10</mass>
          <inertia>
            <ixx>1</ixx>
            <ixy>0</ixy>
            <ixz>0</ixz>
            <iyy>1</iyy>
            <iyz>0</iyz>
            <izz>1</izz>
          </inertia>
        </inertial>
        <collision name='front_right_wheel_collision'>
          <geometry>
            <cylinder>
              <radius>0.21</radius>
              <length>0.1</length>
            </cylinder>
          </geometry>
          <max_contacts>10</max_contacts>
          <surface>
            <contact>
              <ode/>
            </contact>
            <bounce/>
            <friction>
              <ode/>
            </friction>
          </surface>
        </collision>
        <visual name='front_right_wheel_visual'>
          <geometry>
            <mesh>
              <uri>/Users/selfcar/Desktop/Self-Driving-Comps/models/sdcCar/wheel.stl</uri>
            </mesh>
          </geometry>
          <material>
            <script>
              <uri>file://media/materials/scripts/gazebo.material</uri>
              <name>Gazebo/Black</name>
            </script>
          </material>
        </visual>
        <self_collide>0</self_collide>
        <kinematic>0</kinematic>
        <gravity>1</gravity>
      </link>
      <link name='back_right_wheel'>
        <pose>-0.87 -0.5 0.3 0 1.57079 -1.57079</pose>
        <inertial>
          <mass>10</mass>
          <inertia>
            <ixx>1</ixx>
            <ixy>0</ixy>
            <ixz>0</ixz>
            <iyy>1</iyy>
            <iyz>0</iyz>
            <izz>1</izz>
          </inertia>
        </inertial>
        <collision name='back_right_wheel_collision'>
          <geometry>
            <cylinder>
              <radius>0.21</radius>
              <length>0.1</length>
            </cylinder>
          </geometry>
          <max_contacts>10</max_contacts>
          <surface>
            <contact>
              <ode/>
            </contact>
            <bounce/>
            <friction>
              <ode/>
            </friction>
          </surface>
        </collision>
        <visual name='back_right_wheel_visual'>
          <geometry>
            <mesh>
              <uri>/Users/selfcar/Desktop/Self-Driving-Comps/models/sdcCar/wheel.stl</uri>
            </mesh>
          </geometry>
          <material>
            <script>
              <uri>file://media/materials/scripts/gazebo.material</uri>
              <name>Gazebo/Black</name>
            </script>
          </material>
        </visual>
        <self_collide>0</self_collide>
        <kinematic>0</kinematic>
        <gravity>1</gravity>
      </link>
      <link name='back_left_wheel'>
        <pose>-0.87 0.5 0.3 0 1.57079 1.57079</pose>
        <inertial>
          <mass>10</mass>
          <inertia>
            <ixx>1</ixx>
            <ixy>0</ixy>
            <ixz>0</ixz>
            <iyy>1</iyy>
            <iyz>0</iyz>
            <izz>1</izz>
          </inertia>
        </inertial>
        <collision name='back_left_wheel_collision'>
          <geometry>
            <cylinder>
              <radius>0.21</radius>
              <length>0.1</length>
            </cylinder>
          </geometry>
          <max_contacts>10</max_contacts>
          <surface>
            <contact>
              <ode/>
            </contact>
            <bounce/>
            <friction>
              <ode/>
            </friction>
          </surface>
        </collision>
        <visual name='back_left_wheel_visual'>
          <geometry>
            <mesh>
              <uri>/Users/selfcar/Desktop/Self-Driving-Comps/models/sdcCar/wheel.stl</uri>
            </mesh>
          </geometry>
          <material>
            <script>
              <uri>file://media/materials/scripts/gazebo.material</uri>
              <name>Gazebo/Black</name>
            </script>
          </material>
        </visual>
        <self_collide>0</self_collide>
        <kinematic>0</kinematic>
        <gravity>1</gravity>
      </link>
      <joint name='front_left_joint' type='revolute2'>
        <parent>chassis</parent>
        <child>front_left_wheel</child>
        <axis>
          <xyz>0 0 1</xyz>
          <limit>
            <lower>0.0063662</lower>
            <upper>0.0063662</upper>
          </limit>
          <use_parent_model_frame>1</use_parent_model_frame>
          <dynamics>
            <spring_reference>0</spring_reference>
            <spring_stiffness>0</spring_stiffness>
          </dynamics>
        </axis>
        <axis2>
          <xyz>0 1 0</xyz>
          <use_parent_model_frame>1</use_parent_model_frame>
          <dynamics>
            <spring_reference>0</spring_reference>
            <spring_stiffness>0</spring_stiffness>
          </dynamics>
        </axis2>
        <physics>
          <ode>
            <limit>
              <cfm>0</cfm>
              <erp>0.9</erp>
            </limit>
            <suspension>
              <cfm>0.01</cfm>
              <erp>0.15</erp>
            </suspension>
          </ode>
        </physics>
      </joint>
      <joint name='front_right_joint' type='revolute2'>
        <parent>chassis</parent>
        <child>front_right_wheel</child>
        <axis>
          <xyz>0 0 1</xyz>
          <limit>
            <lower>0.0063662</lower>
            <upper>0.0063662</upper>
          </limit>
          <use_parent_model_frame>1</use_parent_model_frame>
          <dynamics>
            <spring_reference>0</spring_reference>
            <spring_stiffness>0</spring_stiffness>
          </dynamics>
        </axis>
        <axis2>
          <xyz>0 1 0</xyz>
          <use_parent_model_frame>1</use_parent_model_frame>
          <dynamics>
            <spring_reference>0</spring_reference>
            <spring_stiffness>0</spring_stiffness>
          </dynamics>
        </axis2>
        <physics>
          <ode>
            <limit>
              <cfm>0</cfm>
              <erp>0.9</erp>
            </limit>
            <suspension>
              <cfm>0.01</cfm>
              <erp>0.15</erp>
            </suspension>
          </ode>
        </physics>
      </joint>
      <joint name='back_right_joint' type='revolute2'>
        <parent>chassis</parent>
        <child>back_right_wheel</child>
        <axis>
          <xyz>0 0 1</xyz>
          <limit>
            <lower>0</lower>
            <upper>0</upper>
          </limit>
          <use_parent_model_frame>1</use_parent_model_frame>
          <dynamics>
            <spring_reference>0</spring_reference>
            <spring_stiffness>0</spring_stiffness>
          </dynamics>
        </axis>
        <axis2>
          <xyz>0 1 0</xyz>
          <use_parent_model_frame>1</use_parent_model_frame>
          <dynamics>
            <spring_reference>0</spring_reference>
            <spring_stiffness>0</spring_stiffness>
          </dynamics>
        </axis2>
        <physics>
          <ode>
            <limit>
              <cfm>0</cfm>
              <erp>0.9</erp>
            </limit>
            <suspension>
              <cfm>0.01</cfm>
              <erp>0.15</erp>
            </suspension>
          </ode>
        </physics>
      </joint>
      <joint name='back_left_joint' type='revolute2'>
        <parent>chassis</parent>
        <child>back_left_wheel</child>
        <axis>
          <xyz>0 0 1</xyz>
          <limit>
            <lower>0</lower>
            <upper>0</upper>
          </limit>
          <use_parent_model_frame>1</use_parent_model_frame>
          <dynamics>
            <spring_reference>0</spring_reference>
            <spring_stiffness>0</spring_stiffness>
          </dynamics>
        </axis>
        <axis2>
          <xyz>0 1 0</xyz>
          <use_parent_model_frame>1</use_parent_model_frame>
          <dynamics>
            <spring_reference>0</spring_reference>
            <spring_stiffness>0</spring_stiffness>
          </dynamics>
        </axis2>
        <physics>
          <ode>
            <limit>
              <cfm>0</cfm>
              <erp>0.9</erp>
            </limit>
            <suspension>
              <cfm>0.01</cfm>
              <erp>0.15</erp>
            </suspension>
          </ode>
        </physics>
      </joint>
      <link name='front_lidar'>
        <pose>1 0 0.4 0 -0 0</pose>
        <visual name='front_lidar_visual'>
          <geometry>
            <mesh>
              <uri>model://hokuyo/meshes/hokuyo.dae</uri>
            </mesh>
          </geometry>
        </visual>
        <collision name='front_lidar_collision-base'>
          <pose>0 0 -0.0145 0 -0 0</pose>
          <geometry>
            <box>
              <size>0.05 0.05 0.041</size>
            </box>
          </geometry>
          <max_contacts>10</max_contacts>
          <surface>
            <contact>
              <ode/>
            </contact>
            <bounce/>
            <friction>
              <ode/>
            </friction>
          </surface>
        </collision>
        <collision name='front_lidar_collision-top'>
          <pose>0 0 0.0205 0 -0 0</pose>
          <geometry>
            <cylinder>
              <radius>0.021</radius>
              <length>0.029</length>
            </cylinder>
          </geometry>
          <max_contacts>10</max_contacts>
          <surface>
            <contact>
              <ode/>
            </contact>
            <bounce/>
            <friction>
              <ode/>
            </friction>
          </surface>
        </collision>
        <sensor name='front_lidar' type='ray'>
          <pose>0.01 0 0.0175 0 -0 0</pose>
          <ray>
            <scan>
              <horizontal>
                <samples>640</samples>
                <resolution>1</resolution>
                <min_angle>-1.39626</min_angle>
                <max_angle>1.39626</max_angle>
              </horizontal>
            </scan>
            <range>
              <min>0.08</min>
              <max>20</max>
              <resolution>0.01</resolution>
            </range>
          </ray>
          <plugin name='sdcLaserSensor' filename='build/libsdcLaserSensor.so'/>
          <always_on>1</always_on>
          <update_rate>30</update_rate>
          <visualize>1</visualize>
        </sensor>
        <self_collide>0</self_collide>
        <inertial>
          <inertia>
            <ixx>1</ixx>
            <ixy>0</ixy>
            <ixz>0</ixz>
            <iyy>1</iyy>
            <iyz>0</iyz>
            <izz>1</izz>
          </inertia>
          <mass>1</mass>
        </inertial>
        <kinematic>0</kinematic>
        <gravity>1</gravity>
      </link>
      <joint name='front_lidar_joint' type='revolute'>
        <child>front_lidar</child>
        <parent>chassis</parent>
        <axis>
          <xyz>0 0 1</xyz>
          <limit>
            <upper>0</upper>
            <lower>0</lower>
          </limit>
          <use_parent_model_frame>1</use_parent_model_frame>
          <dynamics>
            <spring_reference>0</spring_reference>
            <spring_stiffness>0</spring_stiffness>
          </dynamics>
        </axis>
      </joint>
      <link name='top_laser'>
        <pose>0 0 1 0 -0 0</pose>
        <visual name='top_laser_visual'>
          <geometry>
            <mesh>
              <uri>model://hokuyo/meshes/hokuyo.dae</uri>
            </mesh>
          </geometry>
        </visual>
        <collision name='top_laser_collision-base'>
          <pose>0 0 -0.0145 0 -0 0</pose>
          <geometry>
            <box>
              <size>0.05 0.05 0.041</size>
            </box>
          </geometry>
          <max_contacts>10</max_contacts>
          <surface>
            <contact>
              <ode/>
            </contact>
            <bounce/>
            <friction>
              <ode/>
            </friction>
          </surface>
        </collision>
        <collision name='top_laser_collision-top'>
          <pose>0 0 0.0205 0 -0 0</pose>
          <geometry>
            <cylinder>
              <radius>0.021</radius>
              <length>0.029</length>
            </cylinder>
          </geometry>
          <max_contacts>10</max_contacts>
          <surface>
            <contact>
              <ode/>
            </contact>
            <bounce/>
            <friction>
              <ode/>
            </friction>
          </surface>
        </collision>
        <sensor name='top_left_laser' type='ray'>
          <pose>0.01 0 0.0175 0 0.18 1.5708</pose>
          <ray>
            <scan>
              <horizontal>
                <samples>160</samples>
                <resolution>1</resolution>
                <min_angle>-0.7854</min_angle>
                <max_angle>0.7854</max_angle>
              </horizontal>
            </scan>
            <range>
              <min>0.08</min>
              <max>20</max>
              <resolution>0.01</resolution>
            </range>
          </ray>
          <plugin name='sdcTopLaserSensor' filename='build/libsdcTopLaserSensor.so'/>
          <always_on>1</always_on>
          <update_rate>30</update_rate>
          <visualize>0</visualize>
        </sensor>
        <sensor name='top_forward_laser' type='ray'>
          <pose>0.01 0 0.0175 0 0.18 0</pose>
          <ray>
            <scan>
              <horizontal>
                <samples>160</samples>
                <resolution>1</resolution>
                <min_angle>-0.7854</min_angle>
                <max_angle>0.7854</max_angle>
              </horizontal>
            </scan>
            <range>
              <min>0.08</min>
              <max>20</max>
              <resolution>0.01</resolution>
            </range>
          </ray>
          <plugin name='sdcTopLaserSensor' filename='build/libsdcTopLaserSensor.so'/>
          <always_on>1</always_on>
          <update_rate>30</update_rate>
          <visualize>0</visualize>
        </sensor>
        <sensor name='top_backward_laser' type='ray'>
          <pose>0.01 0 0.0175 -0 0.18 3.14159</pose>
          <ray>
            <scan>
              <horizontal>
                <samples>160</samples>
                <resolution>1</resolution>
                <min_angle>-0.7854</min_angle>
                <max_angle>0.7854</max_angle>
              </horizontal>
            </scan>
            <range>
              <min>0.08</min>
              <max>20</max>
              <resolution>0.01</resolution>
            </range>
          </ray>
          <plugin name='sdcTopLaserSensor' filename='build/libsdcTopLaserSensor.so'/>
          <always_on>1</always_on>
          <update_rate>30</update_rate>
          <visualize>0</visualize>
        </sensor>
        <sensor name='top_right_laser' type='ray'>
          <pose>0.01 0 0.0175 0 0.18 -1.5708</pose>
          <ray>
            <scan>
              <horizontal>
                <samples>160</samples>
                <resolution>1</resolution>
                <min_angle>-0.7854</min_angle>
                <max_angle>0.7854</max_angle>
              </horizontal>
            </scan>
            <range>
              <min>0.08</min>
              <max>20</max>
              <resolution>0.01</resolution>
            </range>
          </ray>
          <plugin name='sdcTopLaserSensor' filename='build/libsdcTopLaserSensor.so'/>
          <always_on>1</always_on>
          <update_rate>30</update_rate>
          <visualize>0</visualize>
        </sensor>
        <self_collide>0</self_collide>
        <inertial>
          <inertia>
            <ixx>1</ixx>
            <ixy>0</ixy>
            <ixz>0</ixz>
            <iyy>1</iyy>
            <iyz>0</iyz>
            <izz>1</izz>
          </inertia>
          <mass>1</mass>
        </inertial>
        <kinematic>0</kinematic>
        <gravity>1</gravity>
      </link>
      <joint name='top_laser_joint' type='revolute'>
        <child>top_laser</child>
        <parent>chassis</parent>
        <axis>
          <xyz>0 0 1</xyz>
          <limit>
            <upper>0</upper>
            <lower>0</lower>
          </limit>
          <use_parent_model_frame>1</use_parent_model_frame>
          <dynamics>
            <spring_reference>0</spring_reference>
            <spring_stiffness>0</spring_stiffness>
          </dynamics>
        </axis>
      </joint>
      <link name='side_right_sensors'>
        <pose>0 -0.55 0.4 0 -0 0</pose>
        <visual name='side_right_sensors_visual'>
          <geometry>
            <mesh>
              <uri>model://hokuyo/meshes/hokuyo.dae</uri>
            </mesh>
          </geometry>
        </visual>
        <collision name='side_right_sensors_collision-base'>
          <pose>0 0 -0.0145 0 -0 0</pose>
          <geometry>
            <box>
              <size>0.05 0.05 0.041</size>
            </box>
          </geometry>
          <max_contacts>10</max_contacts>
          <surface>
            <contact>
              <ode/>
            </contact>
            <bounce/>
            <friction>
              <ode/>
            </friction>
          </surface>
        </collision>
        <collision name='side_right_sensors_collision-top'>
          <pose>0 0 0.0205 0 -0 0</pose>
          <geometry>
            <cylinder>
              <radius>0.021</radius>
              <length>0.029</length>
            </cylinder>
          </geometry>
          <max_contacts>10</max_contacts>
          <surface>
            <contact>
              <ode/>
            </contact>
            <bounce/>
            <friction>
              <ode/>
            </friction>
          </surface>
        </collision>
        <sensor name='side_right_front_laser' type='ray'>
          <pose>0.4 -0.02 0 0 0 -1.5708</pose>
          <ray>
            <scan>
              <horizontal>
                <samples>160</samples>
                <resolution>1</resolution>
                <min_angle>-1.3</min_angle>
                <max_angle>1.3</max_angle>
              </horizontal>
            </scan>
            <range>
              <min>0.08</min>
              <max>0.8</max>
              <resolution>0.01</resolution>
            </range>
          </ray>
          <plugin name='sdcSideRightSensor' filename='build/libsdcSideRightSensor.so'/>
          <always_on>1</always_on>
          <update_rate>30</update_rate>
          <visualize>0</visualize>
        </sensor>
        <sensor name='side_right_back_laser' type='ray'>
          <pose>-0.6 -0.02 0 0 0 -1.5708</pose>
          <ray>
            <scan>
              <horizontal>
                <samples>160</samples>
                <resolution>1</resolution>
                <min_angle>-1.3</min_angle>
                <max_angle>1.3</max_angle>
              </horizontal>
            </scan>
            <range>
              <min>0.08</min>
              <max>0.8</max>
              <resolution>0.01</resolution>
            </range>
          </ray>
          <plugin name='sdcSideRightSensor' filename='build/libsdcSideRightSensor.so'/>
          <always_on>1</always_on>
          <update_rate>30</update_rate>
          <visualize>0</visualize>
        </sensor>
        <self_collide>0</self_collide>
        <inertial>
          <inertia>
            <ixx>1</ixx>
            <ixy>0</ixy>
            <ixz>0</ixz>
            <iyy>1</iyy>
            <iyz>0</iyz>
            <izz>1</izz>
          </inertia>
          <mass>1</mass>
        </inertial>
        <kinematic>0</kinematic>
        <gravity>1</gravity>
      </link>
      <joint name='side_right_sensor_joint' type='revolute'>
        <child>side_right_sensors</child>
        <parent>chassis</parent>
        <axis>
          <xyz>0 0 1</xyz>
          <limit>
            <upper>0</upper>
            <lower>0</lower>
          </limit>
          <use_parent_model_frame>1</use_parent_model_frame>
          <dynamics>
            <spring_reference>0</spring_reference>
            <spring_stiffness>0</spring_stiffness>
          </dynamics>
        </axis>
      </joint>
      <link name='side_left_sensors'>
        <pose>0 0.55 0.4 0 -0 0</pose>
        <visual name='side_left_sensors_visual'>
          <geometry>
            <mesh>
              <uri>model://hokuyo/meshes/hokuyo.dae</uri>
            </mesh>
          </geometry>
        </visual>
        <collision name='side_left_sensors_collision-base'>
          <pose>0 0 -0.0145 0 -0 0</pose>
          <geometry>
            <box>
              <size>0.05 0.05 0.041</size>
            </box>
          </geometry>
          <max_contacts>10</max_contacts>
          <surface>
            <contact>
              <ode/>
            </contact>
            <bounce/>
            <friction>
              <ode/>
            </friction>
          </surface>
        </collision>
        <collision name='side_left_sensors_collision-top'>
          <pose>0 0 0.0205 0 -0 0</pose>
          <geometry>
            <cylinder>
              <radius>0.021</radius>
              <length>0.029</length>
            </cylinder>
          </geometry>
          <max_contacts>10</max_contacts>
          <surface>
            <contact>
              <ode/>
            </contact>
            <bounce/>
            <friction>
              <ode/>
            </friction>
          </surface>
        </collision>
        <sensor name='side_left_front_laser' type='ray'>
          <pose>0.4 0.02 0 0 -0 1.5708</pose>
          <ray>
            <scan>
              <horizontal>
                <samples>160</samples>
                <resolution>1</resolution>
                <min_angle>-1.3</min_angle>
                <max_angle>1.3</max_angle>
              </horizontal>
            </scan>
            <range>
              <min>0.08</min>
              <max>0.8</max>
              <resolution>0.01</resolution>
            </range>
          </ray>
          <plugin name='sdcSideLeftSensor' filename='build/libsdcSideLeftSensor.so'/>
          <always_on>1</always_on>
          <update_rate>30</update_rate>
          <visualize>0</visualize>
        </sensor>
        <sensor name='side_left_back_laser' type='ray'>
          <pose>-0.6 0.02 0 0 -0 1.5708</pose>
          <ray>
            <scan>
              <horizontal>
                <samples>160</samples>
                <resolution>1</resolution>
                <min_angle>-1.3</min_angle>
                <max_angle>1.3</max_angle>
              </horizontal>
            </scan>
            <range>
              <min>0.08</min>
              <max>0.8</max>
              <resolution>0.01</resolution>
            </range>
          </ray>
          <plugin name='sdcSideLeftSensor' filename='build/libsdcSideLeftSensor.so'/>
          <always_on>1</always_on>
          <update_rate>30</update_rate>
          <visualize>0</visualize>
        </sensor>
        <self_collide>0</self_collide>
        <inertial>
          <inertia>
            <ixx>1</ixx>
            <ixy>0</ixy>
            <ixz>0</ixz>
            <iyy>1</iyy>
            <iyz>0</iyz>
            <izz>1</izz>
          </inertia>
          <mass>1</mass>
        </inertial>
        <kinematic>0</kinematic>
        <gravity>1</gravity>
      </link>
      <joint name='side_left_sensor_joint' type='revolute'>
        <child>side_left_sensors</child>
        <parent>chassis</parent>
        <axis>
          <xyz>0 0 1</xyz>
          <limit>
            <upper>0</upper>
            <lower>0</lower>
          </limit>
          <use_parent_model_frame>1</use_parent_model_frame>
          <dynamics>
            <spring_reference>0</spring_reference>
            <spring_stiffness>0</spring_stiffness>
          </dynamics>
        </axis>
      </joint>
      <link name='camera::link'>
        <pose>0.65 0 0.85 0 0.008 0</pose>
        <self_collide>0</self_collide>
        <kinematic>0</kinematic>
        <sensor name='camera' type='multicamera'>
          <always_on>1</always_on>
          <update_rate>24</update_rate>
          <visualize>0</visualize>
          <topic>comps_car_camera</topic>
          <camera name='left'>
            <pose>0 0.2 0 0 -0 0</pose>
            <horizontal_fov>1.047</horizontal_fov>
            <image>
              <width>640</width>
              <height>480</height>
            </image>
            <clip>
              <near>0.1</near>
              <far>150</far>
            </clip>
            <save enabled='0'>
              <path>/Users/selfcar/Desktop/Self-Driving-Comps/comps_camera_recordings/</path>
            </save>
          </camera>
          <camera name='right'>
            <pose>0 -0.2 0 0 -0 0</pose>
            <horizontal_fov>1.047</horizontal_fov>
            <image>
              <width>640</width>
              <height>480</height>
            </image>
            <clip>
              <near>0.1</near>
              <far>150</far>
            </clip>
            <save enabled='0'>
              <path>/Users/selfcar/Desktop/Self-Driving-Comps/comps_camera_recordings/</path>
            </save>
          </camera>
          <plugin name='sdcCameraSensor' filename='build/libsdcCameraSensor.so'/>
        </sensor>
        <visual name='visual'>
          <geometry>
            <box>
              <size>0.1 0.1 0.1</size>
            </box>
          </geometry>
          <material>
            <shader type='pixel'/>
          </material>
          <pose>0 0 0 0 -0 0</pose>
          <cast_shadows>1</cast_shadows>
          <transparency>0</transparency>
        </visual>
        <inertial>
          <inertia>
            <ixx>1</ixx>
            <ixy>0</ixy>
            <ixz>0</ixz>
            <iyy>1</iyy>
            <iyz>0</iyz>
            <izz>1</izz>
          </inertia>
          <mass>1</mass>
        </inertial>
        <gravity>1</gravity>
      </link>
      <joint name='camera' type='revolute'>
        <parent>chassis</parent>
        <child>camera::link</child>
        <axis>
          <xyz>0 0 1</xyz>
          <use_parent_model_frame>0</use_parent_model_frame>
          <limit>
            <lower>0</lower>
            <upper>0</upper>
            <effort>-1</effort>
            <velocity>-1</velocity>
          </limit>
          <dynamics>
            <spring_reference>0</spring_reference>
            <spring_stiffness>0</spring_stiffness>
            <damping>0</damping>
            <friction>0</friction>
          </dynamics>
          <use_parent_model_frame>1</use_parent_model_frame>
        </axis>
        <physics>
          <ode>
            <limit>
              <cfm>0</cfm>
              <erp>0.2</erp>
            </limit>
            <suspension>
              <cfm>0</cfm>
              <erp>0.2</erp>
            </suspension>
          </ode>
        </physics>
      </joint>
      <link name='gps'>
        <pose>0 0 1 0 -0 0</pose>
        <visual name='visual'>
          <geometry>
            <mesh>
              <uri>model://hokuyo/meshes/hokuyo.dae</uri>
            </mesh>
          </geometry>
        </visual>
        <collision name='gps_collision-base'>
          <pose>0 0 -0.0145 0 -0 0</pose>
          <geometry>
            <box>
              <size>0.05 0.05 0.041</size>
            </box>
          </geometry>
          <max_contacts>10</max_contacts>
          <surface>
            <contact>
              <ode/>
            </contact>
            <bounce/>
            <friction>
              <ode/>
            </friction>
          </surface>
        </collision>
        <collision name='gps_collision-top'>
          <pose>0 0 0.0205 0 -0 0</pose>
          <geometry>
            <cylinder>
              <radius>0.021</radius>
              <length>0.029</length>
            </cylinder>
          </geometry>
          <max_contacts>10</max_contacts>
          <surface>
            <contact>
              <ode/>
            </contact>
            <bounce/>
            <friction>
              <ode/>
            </friction>
          </surface>
        </collision>
        <sensor name='gps' type='gps'>
          <pose>0 0 0 0 -0 0</pose>
          <plugin name='sdcGpsSensor' filename='build/libsdcGpsSensor.so'/>
          <always_on>1</always_on>
          <update_rate>30</update_rate>
        </sensor>
        <self_collide>0</self_collide>
        <inertial>
          <inertia>
            <ixx>1</ixx>
            <ixy>0</ixy>
            <ixz>0</ixz>
            <iyy>1</iyy>
            <iyz>0</iyz>
            <izz>1</izz>
          </inertia>
          <mass>1</mass>
        </inertial>
        <kinematic>0</kinematic>
        <gravity>1</gravity>
      </link>
      <joint name='gps_joint' type='revolute'>
        <child>gps</child>
        <parent>chassis</parent>
        <axis>
          <xyz>0 0 1</xyz>
          <limit>
            <upper>0</upper>
            <lower>0</lower>
          </limit>
          <use_parent_model_frame>1</use_parent_model_frame>
          <dynamics>
            <spring_reference>0</spring_reference>
            <spring_stiffness>0</spring_stiffness>
          </dynamics>
        </axis>
      </joint>
      <plugin name='sdcCar' filename='build/libsdcCar.so'>
        <front_left>front_left_joint</front_left>
        <front_right>front_right_joint</front_right>
        <back_left>back_left_joint</back_left>
        <back_right>back_right_joint</back_right>
        <chassis>chassis</chassis>
        <wheel_radius>0.21</wheel_radius>
        <front_power>10</front_power>
        <rear_power>10</rear_power>
        <tire_angle_range>0.5</tire_angle_range>
        <max_speed>10</max_speed>
        <aero_load>1.0</aero_load>
      </plugin>
      <pose>-2.52011 -1 0 0 -0 0</pose>
    </model>
    <state world_name='default'>
      <sim_time>42 56000000</sim_time>
      <real_time>3 407706000</real_time>
      <wall_time>1455302755 307837000</wall_time>
      <iterations>3323</iterations>
      <model name='Paris_segment'>
        <pose>6.86053 -3.66978 0 0 -0 1.60403</pose>
        <link name='link_0'>
          <pose>6.86052 -3.66978 1e-06 0 -0 1.60403</pose>
          <velocity>0 0 0 0 -0 0</velocity>
          <acceleration>0 0 0 0 -0 0</acceleration>
          <wrench>0 0 0 0 -0 0</wrench>
        </link>
      </model>
      <model name='car'>
        <pose>13.3896 -4.05755 -0.219031 -1.4e-05 -0.002006 0.00164</pose>
        <link name='back_left_wheel'>
          <pose>12.5353 -3.55895 0.114242 -1.57081 -0.039008 0.001647</pose>
          <velocity>2.84094 0.004733 7e-06 -0.022541 0.964549 -0.011277</velocity>
          <acceleration>-0.659887 -0.066233 -0.005843 -2.82636 -0.061504 2.76105</acceleration>
          <wrench>-6.59886 -0.662327 -0.058432 0 -0 0</wrench>
        </link>
        <link name='back_right_wheel'>
          <pose>12.5368 -4.55894 0.114206 1.57078 0.074851 0.001632</pose>
          <velocity>2.80385 0.004627 -0.036979 -0.022389 0.795927 -0.011203</velocity>
          <acceleration>-0.584138 -0.098542 -37.0101 0.118902 -0.93264 -0.305283</acceleration>
          <wrench>-5.84138 -0.985416 -370.101 0 -0 0</wrench>
        </link>
        <link name='camera::link'>
          <pose>14.0379 -4.05647 0.632271 -1.4e-05 0.005994 0.00164</pose>
          <velocity>2.82036 -0.01132 0.383612 -0.000349 -0.008336 -0.010669</velocity>
          <acceleration>2.21503 -0.039019 0.315925 0.09649 -0.338442 0.262295</acceleration>
          <wrench>2.21503 -0.039019 0.315925 0 -0 0</wrench>
        </link>
        <link name='chassis'>
          <pose>13.3889 -4.05755 0.130968 -1.4e-05 -0.002006 0.00164</pose>
          <velocity>2.82453 -0.004575 0.378203 -0.000341 -0.008335 -0.010667</velocity>
          <acceleration>2.38705 -0.157651 0.095674 0.116881 -0.339522 0.266735</acceleration>
          <wrench>238.705 -15.7651 9.56739 0 -0 0</wrench>
        </link>
        <link name='front_left_wheel'>
          <pose>14.2052 -3.55632 0.114242 -1.57079 0.168949 -0.004719</pose>
          <velocity>2.79287 -0.013125 0.010011 0.06252 0.735607 -0.01081</velocity>
          <acceleration>-0.820948 0.031122 34.3361 3.08464 0.06452 -1.67668</acceleration>
          <wrench>-8.20948 0.311216 343.361 0 -0 0</wrench>
        </link>
        <link name='front_lidar'>
          <pose>14.3888 -4.05591 0.182974 -1.5e-05 -0.002006 0.00164</pose>
          <velocity>2.82411 -0.015224 0.38654 -0.000384 -0.008336 -0.010683</velocity>
          <acceleration>2.36747 0.048083 0.430283 0.031567 -0.333091 0.209578</acceleration>
          <wrench>2.36747 0.048083 0.430283 0 -0 0</wrench>
        </link>
        <link name='front_right_wheel'>
          <pose>14.2064 -4.55631 0.114242 1.57079 0.293092 -0.004731</pose>
          <velocity>2.75515 -0.012893 0.010071 0.061391 0.552999 -0.009109</velocity>
          <acceleration>-0.244156 0.216132 37.3498 0.783004 -0.427243 3.04687</acceleration>
          <wrench>-2.44156 2.16132 373.498 0 -0 0</wrench>
        </link>
        <link name='gps'>
          <pose>13.3876 -4.05754 0.780967 -1.4e-05 -0.002006 0.00164</pose>
          <velocity>2.81911 -0.004337 0.378192 -0.000351 -0.008334 -0.010664</velocity>
          <acceleration>2.16492 -0.229674 0.095191 0.101469 -0.338991 0.266506</acceleration>
          <wrench>2.16492 -0.229674 0.095191 0 -0 0</wrench>
        </link>
        <link name='side_left_sensors'>
          <pose>13.3879 -3.50755 0.18096 -1.5e-05 -0.002006 0.00164</pose>
          <velocity>2.82997 -0.00455 0.378003 -0.000349 -0.008338 -0.010676</velocity>
          <acceleration>2.22651 -0.164903 0.146976 0.087425 -0.337324 0.257182</acceleration>
          <wrench>2.22651 -0.164903 0.146976 0 -0 0</wrench>
        </link>
        <link name='side_right_sensors'>
          <pose>13.3897 -4.60755 0.180976 -1.5e-05 -0.002006 0.00164</pose>
          <velocity>2.81824 -0.004569 0.378402 -0.000353 -0.008339 -0.010683</velocity>
          <acceleration>2.50534 -0.163859 0.049893 0.07346 -0.336478 0.247169</acceleration>
          <wrench>2.50534 -0.163859 0.049893 0 -0 0</wrench>
        </link>
        <link name='top_laser'>
          <pose>13.3876 -4.05754 0.780967 -1.5e-05 -0.002006 0.00164</pose>
          <velocity>2.8191 -0.004333 0.378192 -0.000365 -0.008339 -0.010686</velocity>
          <acceleration>2.16658 -0.203744 0.095205 0.051929 -0.335925 0.238531</acceleration>
          <wrench>2.16658 -0.203744 0.095205 0 -0 0</wrench>
        </link>
      </model>
    </state>
    <gui fullscreen='0'>
      <camera name='user_camera'>
        <pose>14.4304 1.67295 9.91942 0 0.851643 -2.90299</pose>
        <view_controller>orbit</view_controller>
        <projection_type>perspective</projection_type>
      </camera>
    </gui>
  </world>
</sdf>
