<model name="cart_front_steer">
            <link name="chassis">
                <pose>0 0 0.15  0 0 0</pose>
                <inertial>
                    <pose>0.1 0 0  0 0 0</pose>
                    <mass>10</mass>
                    <inertia>
                        <ixx>0.21666666666666667</ixx>
                        <iyy>0.8416666666666667</iyy>
                        <izz>1.0416666666666667</izz>
                        <ixy>0</ixy>
                        <ixz>0</ixz>
                        <iyz>0</iyz>
                    </inertia>
                </inertial>
                <collision name="collision">
                    <geometry>
                        <box>
                            <size>1.0 0.5 0.1</size>
                        </box>
                    </geometry>
                </collision>
                <visual name="visual">
                    <geometry>
                        <box>
                            <size>1.0 0.5 0.1</size>
                        </box>
                    </geometry>
                    <material>
                        <script>
                            <uri>file://media/materials/scripts/gazebo.material</uri>
                            <name>Gazebo/Grey</name>
                        </script>
                    </material>
                </visual>
            </link>
            
            <link name="wheel_front_left">
                <pose>0.5 0.298 0.15  -1.5707963267948966 -0.08726646259971647 0</pose>
                <inertial>
                    <mass>0.5</mass>
                    <inertia>
                        <ixx>0.0030791666666666667</ixx>
                        <iyy>0.0030791666666666667</iyy>
                        <izz>0.005625</izz>
                        <ixy>0</ixy>
                        <ixz>0</ixz>
                        <iyz>0</iyz>
                    </inertia>
                </inertial>
                <collision name="collision">
                    <geometry>
                        <cylinder>
                            <radius>0.15</radius>
                            <length>0.08</length>
                        </cylinder>
                    </geometry>
                </collision>
                <visual name="visual">
                    <geometry>
                        <cylinder>
                            <radius>0.15</radius>
                            <length>0.08</length>
                        </cylinder>
                    </geometry>
                    <material>
                        <script>
                            <uri>file://media/materials/scripts/gazebo.material</uri>
                            <name>Gazebo/Black</name>
                        </script>
                    </material>
                </visual>
            </link>
            
            <joint name="wheel_front_left_steer_spin" type="universal">
                <parent>chassis</parent>
                <child>wheel_front_left</child>
                <axis>
                    <xyz>0 1 0</xyz>
                    <limit>
                        <lower>-0.6108652381980153</lower>
                        <upper>0.6108652381980153</upper>
                    </limit>
                </axis>
                <axis2>
                    <xyz>0 0 1</xyz>
                </axis2>
            </joint>
            
            <link name="wheel_front_right">
                <pose>0.5 -0.298 0.15  -1.5707963267948966 -0.08726646259971647 0</pose>
                <inertial>
                    <mass>0.5</mass>
                    <inertia>
                        <ixx>0.0030791666666666667</ixx>
                        <iyy>0.0030791666666666667</iyy>
                        <izz>0.005625</izz>
                        <ixy>0</ixy>
                        <ixz>0</ixz>
                        <iyz>0</iyz>
                    </inertia>
                </inertial>
                <collision name="collision">
                    <geometry>
                        <cylinder>
                            <radius>0.15</radius>
                            <length>0.08</length>
                        </cylinder>
                    </geometry>
                </collision>
                <visual name="visual">
                    <geometry>
                        <cylinder>
                            <radius>0.15</radius>
                            <length>0.08</length>
                        </cylinder>
                    </geometry>
                    <material>
                        <script>
                            <uri>file://media/materials/scripts/gazebo.material</uri>
                            <name>Gazebo/Bricks</name>
                        </script>
                    </material>
                </visual>
            </link>
            
            <joint name="wheel_front_right_steer_spin" type="universal">
                <parent>chassis</parent>
                <child>wheel_front_right</child>
                <axis>
                    <xyz>0 1 0</xyz>
                    <limit>
                        <lower>-0.6108652381980153</lower>
                        <upper>0.6108652381980153</upper>
                    </limit>
                </axis>
                <axis2>
                    <xyz>0 0 1</xyz>
                </axis2>
            </joint>
            
            
            <link name="wheel_rear_left">
                <pose>-0.5 0.298 0.15  -1.5707963267948966 0 0</pose>
                <inertial>
                    <mass>0.5</mass>
                    <inertia>
                        <ixx>0.0030791666666666667</ixx>
                        <iyy>0.0030791666666666667</iyy>
                        <izz>0.005625</izz>
                        <ixy>0</ixy>
                        <ixz>0</ixz>
                        <iyz>0</iyz>
                    </inertia>
                </inertial>
                <collision name="collision">
                    <geometry>
                        <cylinder>
                            <radius>0.15</radius>
                            <length>0.08</length>
                        </cylinder>
                    </geometry>
                </collision>
                <visual name="visual">
                    <geometry>
                        <cylinder>
                            <radius>0.15</radius>
                            <length>0.08</length>
                        </cylinder>
                    </geometry>
                    <material>
                        <script>
                            <uri>file://media/materials/scripts/gazebo.material</uri>
                            <name>Gazebo/Black</name>
                        </script>
                    </material>
                </visual>
            </link>
            <joint name="wheel_rear_left_spin" type="revolute">
                <parent>chassis</parent>
                <child>wheel_rear_left</child>
                <axis>
                    <xyz>0 1 0</xyz>
                </axis>
            </joint>
            
            <link name="wheel_rear_right">
                <pose>-0.5 -0.298 0.15  -1.5707963267948966 0 0</pose>
                <inertial>
                    <mass>0.5</mass>
                    <inertia>
                        <ixx>0.0030791666666666667</ixx>
                        <iyy>0.0030791666666666667</iyy>
                        <izz>0.005625</izz>
                        <ixy>0</ixy>
                        <ixz>0</ixz>
                        <iyz>0</iyz>
                    </inertia>
                </inertial>
                <collision name="collision">
                    <geometry>
                        <cylinder>
                            <radius>0.15</radius>
                            <length>0.08</length>
                        </cylinder>
                    </geometry>
                </collision>
                <visual name="visual">
                    <geometry>
                        <cylinder>
                            <radius>0.15</radius>
                            <length>0.08</length>
                        </cylinder>
                    </geometry>
                    <material>
                        <script>
                            <uri>file://media/materials/scripts/gazebo.material</uri>
                            <name>Gazebo/Black</name>
                        </script>
                    </material>
                </visual>
            </link>
            <joint name="wheel_rear_right_spin" type="revolute">
                <parent>chassis</parent>
                <child>wheel_rear_right</child>
                <axis>
                    <xyz>0 1 0</xyz>
                </axis>
            </joint>
            
            <link name="car_laser">
                <pose>0 0 0.2 0 0 0</pose>
                <inertial>
                    <mass>0.1</mass>
                </inertial>
                <visual name="visual">
                    <geometry>
                        <mesh>
                            <uri>model://hokuyo/meshes/hokuyo.dae</uri>
                        </mesh>
                    </geometry>
                </visual>
                <collision name="collision-base">
                    <pose>0 0 -0.0145 0 0 0</pose>
                    <geometry>
                        <box>
                            <size>0.05 0.05 0.041</size>
                        </box>
                    </geometry>
                </collision>
                <collision name="collision-top">
                    <pose>0 0 0.0205 0 0 0</pose>
                    <geometry>
                        <cylinder>
                            <radius>0.021</radius>
                            <length>0.029</length>
                        </cylinder>
                    </geometry>
                </collision>
                <sensor name="laser" type="ray">
                    <pose>0.01 0 0.0175 0 -0 0</pose>
                    <ray>
                        <scan>
                            <horizontal>
                                <samples>640</samples>
                                <resolution>1</resolution>
                                <min_angle>-2.26889</min_angle>
                                <max_angle>2.268899</max_angle>
                            </horizontal>
                        </scan>
                        <range>
                            <min>0.08</min>
                            <max>10</max>
                            <resolution>0.01</resolution>
                        </range>
                    </ray>
                    <plugin name="laser_car" filename="build/liblaser_car.so" />
                    <always_on>1</always_on>
                    <update_rate>30</update_rate>
                    <visualize>true</visualize>
                </sensor>
            </link>
            <joint name="car_laser_joint" type="revolute">
                <child>car_laser</child>
                <parent>chassis</parent>
                <axis>
                    <xyz>0 0 1</xyz>
                    <limit>
                        <upper>0</upper>
                        <lower>0</lower>
                    </limit>
                </axis>
            </joint>
            
            <plugin name="model_car" filename="build/libmodel_car.so"/>
        </model>