<?xml version="1.0" ?>
<sdf version="1.4">

    <model name="car">
        <!-- CHASSIS -->
        <link name="chassis">
            <pose>0 0 0.35 0 0 0</pose>
            <inertial>
                <mass>100.0</mass>
            </inertial>
            <collision name="chassis_collision">
                <geometry>
                    <box><size>2.0 0.8 0.2</size></box>
                </geometry>
            </collision>
            <visual name="chassis_visual">
              <pose>0.1 0 -0.2 0 -0 1.57079</pose>
                <geometry>
                    <mesh>
                        <uri>models/sdcCar/cooper-test.dae</uri>
                    </mesh>
                </geometry>
            </visual>
        </link>

        <!-- FRONT LEFT WHEEL -->
        <link name="front_left_wheel">
            <inertial>
                <mass>10.0</mass>
            </inertial>
            <pose>0.8 0.5 0.3 0 1.57079 1.57079</pose>
            <collision name="front_left_wheel_collision">
                <geometry>
                    <cylinder><radius>0.21</radius><length>0.1</length></cylinder>
                    <!--<mesh><uri>/Users/selfcar/Desktop/Self-Driving-Comps/models/sdcCar/wheel.stl</uri></mesh>-->
                </geometry>
            </collision>
            <visual name="front_left_wheel_visual">
                <geometry>
                  <mesh>
                    <uri>models/sdcCar/wheel.stl</uri>
                  </mesh>
                </geometry>
                <material>
                    <script>
                        <uri>file://media/materials/scripts/gazebo.material</uri>
                        <name>Gazebo/Black</name>
                    </script>
                </material>
            </visual>
        </link>

        <!-- FRONT RIGHT WHEEL -->
        <link name="front_right_wheel">
            <pose>0.8 -0.5 0.3 0 1.57079 -1.57079</pose>
            <inertial>
                <mass>10.0</mass>
            </inertial>
            <collision name="front_right_wheel_collision">
                <geometry>
                    <cylinder><radius>0.21</radius><length>0.1</length></cylinder>
                    <!--<mesh><uri>/Users/selfcar/Desktop/Self-Driving-Comps/models/sdcCar/wheel.stl</uri></mesh>-->
                </geometry>
            </collision>
            <visual name="front_right_wheel_visual">
                <geometry>
                  <mesh>
                    <uri>models/sdcCar/wheel.stl</uri>
                  </mesh>
                </geometry>
                <material>
                    <script>
                        <uri>file://media/materials/scripts/gazebo.material</uri>
                        <name>Gazebo/Black</name>
                    </script>
                </material>
            </visual>
        </link>

        <!-- BACK RIGHT WHEEL -->
        <link name="back_right_wheel">
            <pose>-0.87 -0.5 0.3 0 1.57079 -1.57079</pose>
            <inertial>
                <mass>10.0</mass>
            </inertial>
            <collision name="back_right_wheel_collision">
                <geometry>
                    <cylinder><radius>0.21</radius><length>0.1</length></cylinder>
                    <!--<mesh><uri>/Users/selfcar/Desktop/Self-Driving-Comps/models/sdcCar/wheel.stl</uri></mesh>-->
                </geometry>
            </collision>
            <visual name="back_right_wheel_visual">
                <geometry>
                  <mesh>
                    <uri>models/sdcCar/wheel.stl</uri>
                  </mesh>
                </geometry>
                <material>
                    <script>
                        <uri>file://media/materials/scripts/gazebo.material</uri>
                        <name>Gazebo/Black</name>
                    </script>
                </material>
            </visual>
        </link>

        <!-- BACK LEFT WHEEL -->
        <link name="back_left_wheel">
            <pose>-0.87 0.5 0.3 0 1.57079 1.57079</pose>
            <inertial>
                <mass>10.0</mass>
            </inertial>
            <collision name="back_left_wheel_collision">
                <geometry>
                    <cylinder><radius>0.21</radius><length>0.1</length></cylinder>
                    <!-- <mesh><uri>/Users/selfcar/Desktop/Self-Driving-Comps/models/sdcCar/wheel.stl</uri></mesh> -->
                </geometry>
            </collision>
            <visual name="back_left_wheel_visual">
                <geometry>
                  <mesh>
                    <uri>models/sdcCar/wheel.stl</uri>
                  </mesh>
                </geometry>
                <material>
                    <script>
                        <uri>file://media/materials/scripts/gazebo.material</uri>
                        <name>Gazebo/Black</name>
                    </script>
                </material>
            </visual>
        </link>

        <!-- JOINT BETWEEN THE FRONT LEFT WHEEL AND CAR -->
        <joint type="revolute2" name="front_left_joint">
            <parent>chassis</parent>
            <child>front_left_wheel</child>
            <axis>
                <xyz>0 0 1</xyz>
                <limit>
                    <lower>0</lower>
                    <upper>0</upper>
                </limit>
            </axis>
            <axis2>
                <xyz>0 1 0</xyz>
            </axis2>
            <physics>
                <ode>
                    <limit>
                        <cfm>0.0</cfm>
                        <erp>0.9</erp>
                    </limit>
                    <suspension>
                        <cfm>0.01</cfm>
                        <erp>0.15</erp>
                    </suspension>
                </ode>
            </physics>
        </joint>

        <!-- JOINT BETWEEN THE FRONT RIGHT WHEEL AND CAR -->
        <joint type="revolute2" name="front_right_joint">
            <parent>chassis</parent>
            <child>front_right_wheel</child>
            <axis>
                <xyz>0 0 1</xyz>
                <limit>
                    <lower>0</lower>
                    <upper>0</upper>
                </limit>
            </axis>
            <axis2>
                <xyz>0 1 0</xyz>
            </axis2>
            <physics>
                <ode>
                    <limit>
                        <cfm>0.0</cfm>
                        <erp>0.9</erp>
                    </limit>
                    <suspension>
                        <cfm>0.01</cfm>
                        <erp>0.15</erp>
                    </suspension>
                </ode>
            </physics>
        </joint>

        <!-- JOINT BETWEEN THE BACK RIGHT WHEEL AND CAR -->
        <joint type="revolute2" name="back_right_joint">
            <parent>chassis</parent>
            <child>back_right_wheel</child>
            <axis>
                <xyz>0 0 1</xyz>
                <limit>
                    <lower>0</lower>
                    <upper>0</upper>
                </limit>
            </axis>
            <axis2>
                <xyz>0 1 0</xyz>
            </axis2>
            <physics>
                <ode>
                    <limit>
                        <cfm>0.0</cfm>
                        <erp>0.9</erp>
                    </limit>
                    <suspension>
                        <cfm>0.01</cfm>
                        <erp>0.15</erp>
                    </suspension>
                </ode>
            </physics>
        </joint>

        <!-- JOINT BETWEEN THE BACK LEFT WHEEL AND CAR -->
        <joint type="revolute2" name="back_left_joint">
            <parent>chassis</parent>
            <child>back_left_wheel</child>
            <axis><xyz>0 0 1</xyz>
                <limit>
                    <lower>0</lower>
                    <upper>0</upper>
                </limit>
            </axis>
            <axis2>
                <xyz>0 1 0</xyz>
            </axis2>
            <physics>
                <ode>
                    <limit>
                        <cfm>0.0</cfm>
                        <erp>0.9</erp>
                    </limit>
                    <suspension>
                        <cfm>0.01</cfm>
                        <erp>0.15</erp>
                    </suspension>
                </ode>
            </physics>
        </joint>

          <!-- FRONT LASER SENSOR -->
        <link name="front_lidar">
              <pose>1.0 0 0.4 0 0 0</pose>
              <visual name="front_lidar_visual">
                  <geometry>
                      <mesh>
                          <uri>model://hokuyo/meshes/hokuyo.dae</uri>
                      </mesh>
                  </geometry>
              </visual>
              <collision name="front_lidar_collision-base">
                  <pose>0 0 -0.0145 0 0 0</pose>
                  <geometry>
                      <box>
                          <size>0.05 0.05 0.041</size>
                      </box>
                  </geometry>
              </collision>
              <collision name="front_lidar_collision-top">
                  <pose>0 0 0.0205 0 0 0</pose>
                  <geometry>
                      <cylinder>
                          <radius>0.021</radius>
                          <length>0.029</length>
                      </cylinder>
                  </geometry>
              </collision>
              <sensor name="front_lidar" type="ray">
                  <pose>0.01 0 0.0175 0 -0 0</pose>
                  <ray>
                      <scan>
                          <horizontal>
                              <samples>640</samples>
                              <resolution>1</resolution>
                              <min_angle>-1.39626</min_angle>
                              <max_angle>1.39626</max_angle>
                          </horizontal>
                      </scan>
                      <range>
                          <min>0.08</min>
                          <max>20</max>
                          <resolution>0.01</resolution>
                      </range>
                  </ray>
                  <plugin name="sdcFrontLidarSensor" filename="build/libsdcFrontLidarSensor.so" />
                  <always_on>1</always_on>
                  <update_rate>30</update_rate>
                  <visualize>1</visualize>
              </sensor>
            </link>

        <!-- JOINT BETWEEN THE FRONT LASER SENSOR AND CAR -->
        <joint name="front_lidar_joint" type="revolute">
            <child>front_lidar</child>
            <parent>chassis</parent>
            <axis>
                <xyz>0 0 1</xyz>
                <limit>
                    <upper>0</upper>
                    <lower>0</lower>
                </limit>
            </axis>
        </joint>

        <!-- BACK LASER SENSOR -->
      <link name="back_lidar">
            <pose>-1.2 0 0.4 0 0 0</pose>
            <visual name="back_lidar_visual">
                <geometry>
                    <mesh>
                        <uri>model://hokuyo/meshes/hokuyo.dae</uri>
                    </mesh>
                </geometry>
            </visual>
            <collision name="back_lidar_collision-base">
                <pose>0 0 -0.0145 0 0 0</pose>
                <geometry>
                    <box>
                        <size>0.05 0.05 0.041</size>
                    </box>
                </geometry>
            </collision>
            <collision name="back_lidar_collision-top">
                <pose>0 0 0.0205 0 0 0</pose>
                <geometry>
                    <cylinder>
                        <radius>0.021</radius>
                        <length>0.029</length>
                    </cylinder>
                </geometry>
            </collision>
            <sensor name="back_lidar" type="ray">
                <pose>0.01 0 0.0175 0 3.1459 0</pose>
                <ray>
                    <scan>
                        <horizontal>
                            <samples>120</samples>
                            <resolution>1</resolution>
                            <min_angle>-1.5709</min_angle>
                            <max_angle>1.5709</max_angle>
                        </horizontal>
                    </scan>
                    <range>
                        <min>0.08</min>
                        <max>10</max>
                        <resolution>0.01</resolution>
                    </range>
                </ray>
                <plugin name="sdcBackLidarSensor" filename="build/libsdcBackLidarSensor.so" />
                <always_on>1</always_on>
                <update_rate>30</update_rate>
                <visualize>0</visualize>
            </sensor>
          </link>

      <!-- JOINT BETWEEN THE BACK LASER SENSOR AND CAR -->
      <joint name="back_lidar_joint" type="revolute">
          <child>back_lidar</child>
          <parent>chassis</parent>
          <axis>
              <xyz>0 0 1</xyz>
              <limit>
                  <upper>0</upper>
                  <lower>0</lower>
              </limit>
          </axis>
      </joint>

        <!-- TOP LASER SENSOR -->
        <link name="top_laser">
            <pose>0.0 0 1.1 0.0 0.0 0.0</pose>
            <visual name="top_laser_visual">
                <geometry>
                    <mesh>
                        <uri>model://hokuyo/meshes/hokuyo.dae</uri>
                    </mesh>
                </geometry>
            </visual>
            <collision name="top_laser_collision-base">
                <pose>0 0 -0.0145 0 0 0</pose>
                <geometry>
                    <box>
                        <size>0.05 0.05 0.041</size>
                    </box>
                </geometry>
            </collision>
            <collision name="top_laser_collision-top">
                <pose>0 0 0.0205 0 0 0</pose>
                <geometry>
                    <cylinder>
                        <radius>0.021</radius>
                        <length>0.029</length>
                    </cylinder>
                </geometry>
            </collision>
            <sensor name="top_left_laser" type="ray">
                <pose>0.01 0 0.0175 0 0.18 1.5708</pose>
                <ray>
                    <scan>
                        <horizontal>
                            <samples>160</samples>
                            <resolution>1</resolution>
                            <min_angle>-0.7854</min_angle>
                            <max_angle>0.7854</max_angle>
                        </horizontal>
                    </scan>
                    <range>
                        <min>0.08</min>
                        <max>20</max>
                        <resolution>0.01</resolution>
                    </range>
                </ray>
                <plugin name="sdcTopLidarSensor" filename="build/libsdcTopLidarSensor.so" />
                <always_on>1</always_on>
                <update_rate>30</update_rate>
                <visualize>false</visualize>
            </sensor>
            <sensor name="top_forward_laser" type="ray">
                <pose>0.01 0 0.0175 0 0.18 0</pose>
                <ray>
                    <scan>
                        <horizontal>
                            <samples>160</samples>
                            <resolution>1</resolution>
                            <min_angle>-0.7854</min_angle>
                            <max_angle>0.7854</max_angle>
                        </horizontal>
                    </scan>
                    <range>
                        <min>0.08</min>
                        <max>20</max>
                        <resolution>0.01</resolution>
                    </range>
                </ray>
                <plugin name="sdcTopLidarSensor" filename="build/libsdcTopLidarSensor.so" />
                <always_on>1</always_on>
                <update_rate>30</update_rate>
                <visualize>false</visualize>
            </sensor>
            <sensor name="top_backward_laser" type="ray">
                <pose>0.01 0 0.0175 0 0.18 3.14159</pose>
                <ray>
                    <scan>
                        <horizontal>
                            <samples>160</samples>
                            <resolution>1</resolution>
                            <min_angle>-0.7854</min_angle>
                            <max_angle>0.7854</max_angle>
                        </horizontal>
                    </scan>
                    <range>
                        <min>0.08</min>
                        <max>20</max>
                        <resolution>0.01</resolution>
                    </range>
                </ray>
                <plugin name="sdcTopLidarSensor" filename="build/libsdcTopLidarSensor.so" />
                <always_on>1</always_on>
                <update_rate>30</update_rate>
                <visualize>false</visualize>
            </sensor>
            <sensor name="top_right_laser" type="ray">
                <pose>0.01 0 0.0175 0 0.18 -1.5708</pose>
                <ray>
                    <scan>
                        <horizontal>
                            <samples>160</samples>
                            <resolution>1</resolution>
                            <min_angle>-0.7854</min_angle>
                            <max_angle>0.7854</max_angle>
                        </horizontal>
                    </scan>
                    <range>
                        <min>0.08</min>
                        <max>20</max>
                        <resolution>0.01</resolution>
                    </range>
                </ray>
                <plugin name="sdcTopLidarSensor" filename="build/libsdcTopLidarSensor.so" />
                <always_on>1</always_on>
                <update_rate>30</update_rate>
                <visualize>false</visualize>
            </sensor>
        </link>

        <!-- JOINT BETWEEN THE TOP LASER SENSOR AND CAR -->
        <joint name="top_laser_joint" type="revolute">
            <child>top_laser</child>
            <parent>chassis</parent>
            <axis>
                <xyz>0 0 1</xyz>
                <limit>
                    <upper>0</upper>
                    <lower>0</lower>
                </limit>
            </axis>
        </joint>



        <!-- SIDE SENSORS (PSEUDO-RADAR) -->
        <link name="side_right_sensors">
            <pose>0.0 -0.55 0.4 0.0 0.0 0.0</pose>
            <visual name="side_right_sensors_visual">
                <geometry>
                    <mesh>
                        <uri>model://hokuyo/meshes/hokuyo.dae</uri>
                    </mesh>
                </geometry>
            </visual>
            <collision name="side_right_sensors_collision-base">
                <pose>0 0 -0.0145 0 0 0</pose>
                <geometry>
                    <box>
                        <size>0.05 0.05 0.041</size>
                    </box>
                </geometry>
            </collision>
            <collision name="side_right_sensors_collision-top">
                <pose>0 0 0.0205 0 0 0</pose>
                <geometry>
                    <cylinder>
                        <radius>0.021</radius>
                        <length>0.029</length>
                    </cylinder>
                </geometry>
            </collision>
            <sensor name="side_right_front_laser" type="ray">
                <pose>0.4 -0.02 0.0 0 0.0 -1.5708</pose>
                <ray>
                    <scan>
                        <horizontal>
                            <samples>160</samples>
                            <resolution>1</resolution>
                            <min_angle>-1.3</min_angle>
                            <max_angle>1.3</max_angle>
                        </horizontal>
                    </scan>
                    <range>
                        <min>0.08</min>
                        <max>1.0</max>
                        <resolution>0.01</resolution>
                    </range>
                </ray>
                <plugin name="sdcSideLidarSensor" filename="build/libsdcSideLidarSensor.so" />
                <always_on>1</always_on>
                <update_rate>30</update_rate>
                <visualize>0</visualize>
            </sensor>
            <sensor name="side_right_back_laser" type="ray">
                <pose>-0.6 -0.02 0.0 0 0.0 -1.5708</pose>
                <ray>
                    <scan>
                        <horizontal>
                            <samples>160</samples>
                            <resolution>1</resolution>
                            <min_angle>-1.3</min_angle>
                            <max_angle>1.3</max_angle>
                        </horizontal>
                    </scan>
                    <range>
                        <min>0.08</min>
                        <max>1.0</max>
                        <resolution>0.01</resolution>
                    </range>
                </ray>
                <plugin name="sdcSideLidarSensor" filename="build/libsdcSideLidarSensor.so" />
                <always_on>1</always_on>
                <update_rate>30</update_rate>
                <visualize>0</visualize>
            </sensor>
        </link>

        <joint name="side_right_sensor_joint" type="revolute">
            <child>side_right_sensors</child>
            <parent>chassis</parent>
            <axis>
                <xyz>0 0 1</xyz>
                <limit>
                    <upper>0</upper>
                    <lower>0</lower>
                </limit>
            </axis>
        </joint>

        <link name="side_left_sensors">
            <pose>0.0 0.55 0.4 0.0 0.0 0.0</pose>
            <visual name="side_left_sensors_visual">
                <geometry>
                    <mesh>
                        <uri>model://hokuyo/meshes/hokuyo.dae</uri>
                    </mesh>
                </geometry>
            </visual>
            <collision name="side_left_sensors_collision-base">
                <pose>0 0 -0.0145 0 0 0</pose>
                <geometry>
                    <box>
                        <size>0.05 0.05 0.041</size>
                    </box>
                </geometry>
            </collision>
            <collision name="side_left_sensors_collision-top">
                <pose>0 0 0.0205 0 0 0</pose>
                <geometry>
                    <cylinder>
                        <radius>0.021</radius>
                        <length>0.029</length>
                    </cylinder>
                </geometry>
            </collision>
            <sensor name="side_left_front_laser" type="ray">
                <pose>0.4 0.02 0.0 0 0.0 1.5708</pose>
                <ray>
                    <scan>
                        <horizontal>
                            <samples>160</samples>
                            <resolution>1</resolution>
                            <min_angle>-1.3</min_angle>
                            <max_angle>1.3</max_angle>
                        </horizontal>
                    </scan>
                    <range>
                        <min>0.08</min>
                        <max>1.0</max>
                        <resolution>0.01</resolution>
                    </range>
                </ray>
                <plugin name="sdcSideLidarSensor" filename="build/libsdcSideLidarSensor.so" />
                <always_on>1</always_on>
                <update_rate>30</update_rate>
                <visualize>0</visualize>
            </sensor>
            <sensor name="side_left_back_laser" type="ray">
                <pose>-0.6 0.02 0.0 0 0.0 1.5708</pose>
                <ray>
                    <scan>
                        <horizontal>
                            <samples>160</samples>
                            <resolution>1</resolution>
                            <min_angle>-1.3</min_angle>
                            <max_angle>1.3</max_angle>
                        </horizontal>
                    </scan>
                    <range>
                        <min>0.08</min>
                        <max>1.0</max>
                        <resolution>0.01</resolution>
                    </range>
                </ray>
                <plugin name="sdcSideLidarSensor" filename="build/libsdcSideLidarSensor.so" />
                <always_on>1</always_on>
                <update_rate>30</update_rate>
                <visualize>0</visualize>
            </sensor>
        </link>

        <!-- JOINT BETWEEN THE TOP LASER SENSOR AND CAR -->
        <joint name="side_left_sensor_joint" type="revolute">
            <child>side_left_sensors</child>
            <parent>chassis</parent>
            <axis>
                <xyz>0 0 1</xyz>
                <limit>
                    <upper>0</upper>
                    <lower>0</lower>
                </limit>
            </axis>
        </joint>



        <!-- END SIDE SENSORS -->



        <!-- CAMERA -->
        <link name='camera::link'>
              <pose>0.65 0 0.85 0 0.008 0</pose>

              <self_collide>0</self_collide>
              <kinematic>0</kinematic>

              <sensor name='camera' type='multicamera'>
                <always_on>1</always_on>
                <update_rate>24</update_rate>
                <visualize>0</visualize>
                <topic>comps_car_camera</topic>

                <camera name="left">
                  <pose>0 0 0 0 0 0</pose>
                  <horizontal_fov>1.047</horizontal_fov>
                  <image>
                    <width>640</width>
                    <height>480</height>
                  </image>
                  <clip>
                    <near>0.1</near>
                    <far>150</far>
                  </clip>
                  <save enabled="False">
                   <path>/Users/selfcar/Desktop/Self-Driving-Comps/comps_camera_recordings/</path>
                  </save>
                </camera>

                <!-- <camera name="right">
                  <pose>0 -0.2 0 0 0 0</pose>
                  <horizontal_fov>1.047</horizontal_fov>
                  <image>
                    <width>640</width>
                    <height>480</height>
                  </image>
                  <clip>
                    <near>0.1</near>
                    <far>150</far>
                  </clip>
                  <save enabled="False">
                   <path>/Users/selfcar/Desktop/Self-Driving-Comps/comps_camera_recordings/</path>
                  </save>
                </camera> -->

                <plugin name="sdcCameraSensor" filename="build/libsdcCameraSensor.so" />

              </sensor>

              <visual name='visual'>
                <geometry>
                  <box>
                    <size>0.1 0.1 0.1</size>
                  </box>
                </geometry>
                <material>
                  <shader type='pixel'/>
                </material>
                <pose>0 0 0 0 -0 0</pose>
                <cast_shadows>1</cast_shadows>
                <transparency>0</transparency>
              </visual>
        </link>


        <!-- JOINT BETWEEN CAMERA SENSOR AND CAR -->
        <joint name='camera' type='revolute'>
          <parent>chassis</parent>
          <child>camera::link</child>
          <axis>
            <xyz>0 0 1</xyz>
            <use_parent_model_frame>0</use_parent_model_frame>
            <limit>
              <lower>0</lower>
              <upper>0</upper>
              <effort>-1</effort>
              <velocity>-1</velocity>
            </limit>
            <dynamics>
              <spring_reference>0</spring_reference>
              <spring_stiffness>0</spring_stiffness>
              <damping>0</damping>
              <friction>0</friction>
            </dynamics>
          </axis>
          <physics>
            <ode>
              <limit>
                <cfm>0</cfm>
                <erp>0.2</erp>
              </limit>
              <suspension>
                <cfm>0</cfm>
                <erp>0.2</erp>
              </suspension>
            </ode>
          </physics>
        </joint>

        <!-- GPS SENSOR -->
        <link name="gps">
            <pose>0.0 0.0 1.0 0 0 0</pose>
            <visual name="visual">
                <geometry>
                    <mesh>
                        <uri>model://hokuyo/meshes/hokuyo.dae</uri>
                    </mesh>
                </geometry>
            </visual>
            <collision name="gps_collision-base">
                <pose>0 0 -0.0145 0 0 0</pose>
                <geometry>
                    <box>
                        <size>0.05 0.05 0.041</size>
                    </box>
                </geometry>
            </collision>
            <collision name="gps_collision-top">
                <pose>0 0 0.0205 0 0 0</pose>
                <geometry>
                    <cylinder>
                        <radius>0.021</radius>
                        <length>0.029</length>
                    </cylinder>
                </geometry>
            </collision>
            <sensor name="gps" type="gps">
                <pose>0.0 0 0.0 0 0 0</pose>
                <!-- <plugin name="sdcGpsSensor" filename="build/libsdcGpsSensor.so" /> -->
                <always_on>1</always_on>
                <update_rate>30</update_rate>
            </sensor>
        </link>

        <!-- JOINT BETWEEN GPS SENSOR AND CAR -->
        <joint name="gps_joint" type="revolute">
            <child>gps</child>
            <parent>chassis</parent>
            <axis>
                <xyz>0 0 1</xyz>
                <limit>
                    <upper>0</upper>
                    <lower>0</lower>
                </limit>
            </axis>
        </joint>


        <!-- PLUGINS FOR THE CAR; ESSENTIALLY THE "BRAINS" OF THE CAR -->
        <plugin filename="build/libsdcCar.so" name="sdcCar">
            <!-- Joints for each wheel -->
            <front_left>front_left_joint</front_left>
            <front_right>front_right_joint</front_right>
            <back_left>back_left_joint</back_left>
            <back_right>back_right_joint</back_right>
            <!-- This is the chassis -->
            <chassis>chassis</chassis>
            <!-- Radius of the wheel (DO NOT CHANGE UNLESS YOU ALSO CHANGE THE ACTUAL PARAMETER ABOVE PLS) -->
            <wheel_radius>0.21</wheel_radius>
            <!-- Power is multiplied by "gas" to determine force applied to wheels -->
            <front_power>10</front_power>
            <rear_power>10</rear_power>
            <!-- The angle range the front tires can turn for steering, in radians -->
            <tire_angle_range>0.5</tire_angle_range>
            <!-- Maximum speed for the car in meters/second -->
            <max_speed>10</max_speed>
            <!-- Factor for the down-force applied as the car travels faster -->
            <!-- A larger number increases the down force -->
            <aero_load>1.0</aero_load>
        </plugin>

        <plugin name="sdcGpsSensor" filename="build/libsdcGpsSensor.so">
            <gps>gps</gps>
        </plugin>
    </model>
</sdf>
